Traceback (most recent call last):
  File "/usr/lib/python3/dist-packages/tornado/web.py", line 1569, in _execute
    result = self.prepare()
  File "/usr/lib/python3/dist-packages/tornado/web.py", line 2322, in prepare
    raise HTTPError(self._status_code)
tornado.web.HTTPError: HTTP 404: Not Found
